Traceback (most recent call last):
  File "D:\DEMO\Python_demo\Django_demo\Myflight\venv\lib\site-packages\urllib3\connectionpool.py", line 600, in urlopen
    chunked=chunked)
  File "D:\DEMO\Python_demo\Django_demo\Myflight\venv\lib\site-packages\urllib3\connectionpool.py", line 384, in _make_request
    six.raise_from(e, None)
  File "<string>", line 2, in raise_from
  File "D:\DEMO\Python_demo\Django_demo\Myflight\venv\lib\site-packages\urllib3\connectionpool.py", line 380, in _make_request
    httplib_response = conn.getresponse()
  File "D:\application\anaconda\lib\http\client.py", line 1331, in getresponse
    response.begin()
  File "D:\application\anaconda\lib\http\client.py", line 297, in begin
    version, status, reason = self._read_status()
  File "D:\application\anaconda\lib\http\client.py", line 258, in _read_status
    line = str(self.fp.readline(_MAXLINE + 1), "iso-8859-1")
  File "D:\application\anaconda\lib\socket.py", line 586, in readinto
    return self._sock.recv_into(b)
ConnectionResetError: [WinError 10054] 远程主机强迫关闭了一个现有的连接。

During handling of the above exception, another exception occurred:

Traceback (most recent call last):
  File "D:\DEMO\Python_demo\Django_demo\Myflight\venv\lib\site-packages\requests\adapters.py", line 449, in send
    timeout=timeout
  File "D:\DEMO\Python_demo\Django_demo\Myflight\venv\lib\site-packages\urllib3\connectionpool.py", line 638, in urlopen
    _stacktrace=sys.exc_info()[2])
  File "D:\DEMO\Python_demo\Django_demo\Myflight\venv\lib\site-packages\urllib3\util\retry.py", line 398, in increment
    raise MaxRetryError(_pool, url, error or ResponseError(cause))
urllib3.exceptions.MaxRetryError: HTTPConnectionPool(host='119.97.237.74', port=80): Max retries exceeded with url: http://www.variflight.com/flight/detail/productImg&s=NnBZaWV1VWZYSUZlOEhaVXd4T21WRlVDd2IwPQ==&w=50&h=28&fontSize=13&fontColor=2f3032&background=ffffff?AE71649A58c77= (Caused by ProxyError('Cannot connect to proxy.', ConnectionResetError(10054, '远程主机强迫关闭了一个现有的连接。', None, 10054, None)))

During handling of the above exception, another exception occurred:

Traceback (most recent call last):
  File "D:\DEMO\Python_demo\Django_demo\Myflight\utils\data_get.py", line 372, in get_mesbyurl
    resp = r.get(url)
  File "D:\DEMO\Python_demo\Django_demo\Myflight\venv\lib\site-packages\requests\sessions.py", line 546, in get
    return self.request('GET', url, **kwargs)
  File "D:\DEMO\Python_demo\Django_demo\Myflight\venv\lib\site-packages\requests\sessions.py", line 533, in request
    resp = self.send(prep, **send_kwargs)
  File "D:\DEMO\Python_demo\Django_demo\Myflight\venv\lib\site-packages\requests\sessions.py", line 646, in send
    r = adapter.send(request, **kwargs)
  File "D:\DEMO\Python_demo\Django_demo\Myflight\venv\lib\site-packages\requests\adapters.py", line 510, in send
    raise ProxyError(e, request=request)
requests.exceptions.ProxyError: HTTPConnectionPool(host='119.97.237.74', port=80): Max retries exceeded with url: http://www.variflight.com/flight/detail/productImg&s=NnBZaWV1VWZYSUZlOEhaVXd4T21WRlVDd2IwPQ==&w=50&h=28&fontSize=13&fontColor=2f3032&background=ffffff?AE71649A58c77= (Caused by ProxyError('Cannot connect to proxy.', ConnectionResetError(10054, '远程主机强迫关闭了一个现有的连接。', None, 10054, None)))
Traceback (most recent call last):
  File "D:\DEMO\Python_demo\Django_demo\Myflight\venv\lib\site-packages\urllib3\connectionpool.py", line 600, in urlopen
    chunked=chunked)
  File "D:\DEMO\Python_demo\Django_demo\Myflight\venv\lib\site-packages\urllib3\connectionpool.py", line 384, in _make_request
    six.raise_from(e, None)
  File "<string>", line 2, in raise_from
  File "D:\DEMO\Python_demo\Django_demo\Myflight\venv\lib\site-packages\urllib3\connectionpool.py", line 380, in _make_request
    httplib_response = conn.getresponse()
  File "D:\application\anaconda\lib\http\client.py", line 1331, in getresponse
    response.begin()
  File "D:\application\anaconda\lib\http\client.py", line 297, in begin
    version, status, reason = self._read_status()
  File "D:\application\anaconda\lib\http\client.py", line 258, in _read_status
    line = str(self.fp.readline(_MAXLINE + 1), "iso-8859-1")
  File "D:\application\anaconda\lib\socket.py", line 586, in readinto
    return self._sock.recv_into(b)
ConnectionResetError: [WinError 10054] 远程主机强迫关闭了一个现有的连接。

During handling of the above exception, another exception occurred:

Traceback (most recent call last):
  File "D:\DEMO\Python_demo\Django_demo\Myflight\venv\lib\site-packages\requests\adapters.py", line 449, in send
    timeout=timeout
  File "D:\DEMO\Python_demo\Django_demo\Myflight\venv\lib\site-packages\urllib3\connectionpool.py", line 638, in urlopen
    _stacktrace=sys.exc_info()[2])
  File "D:\DEMO\Python_demo\Django_demo\Myflight\venv\lib\site-packages\urllib3\util\retry.py", line 398, in increment
    raise MaxRetryError(_pool, url, error or ResponseError(cause))
urllib3.exceptions.MaxRetryError: HTTPConnectionPool(host='119.97.237.74', port=80): Max retries exceeded with url: http://www.variflight.com/flight/detail/productImg&s=QWpPYzFxQ0Z1T0xBUTNvMGVKZ0VuNE9RVmJlVkZzUmk=&w=63&h=28&fontSize=13&fontColor=2f3032&background=ffffff?AE71649A58c77= (Caused by ProxyError('Cannot connect to proxy.', ConnectionResetError(10054, '远程主机强迫关闭了一个现有的连接。', None, 10054, None)))

During handling of the above exception, another exception occurred:

Traceback (most recent call last):
  File "D:\DEMO\Python_demo\Django_demo\Myflight\utils\data_get.py", line 422, in get_mesbyurl
    q = r.get(ac)
  File "D:\DEMO\Python_demo\Django_demo\Myflight\venv\lib\site-packages\requests\sessions.py", line 546, in get
    return self.request('GET', url, **kwargs)
  File "D:\DEMO\Python_demo\Django_demo\Myflight\venv\lib\site-packages\requests\sessions.py", line 533, in request
    resp = self.send(prep, **send_kwargs)
  File "D:\DEMO\Python_demo\Django_demo\Myflight\venv\lib\site-packages\requests\sessions.py", line 646, in send
    r = adapter.send(request, **kwargs)
  File "D:\DEMO\Python_demo\Django_demo\Myflight\venv\lib\site-packages\requests\adapters.py", line 510, in send
    raise ProxyError(e, request=request)
requests.exceptions.ProxyError: HTTPConnectionPool(host='119.97.237.74', port=80): Max retries exceeded with url: http://www.variflight.com/flight/detail/productImg&s=QWpPYzFxQ0Z1T0xBUTNvMGVKZ0VuNE9RVmJlVkZzUmk=&w=63&h=28&fontSize=13&fontColor=2f3032&background=ffffff?AE71649A58c77= (Caused by ProxyError('Cannot connect to proxy.', ConnectionResetError(10054, '远程主机强迫关闭了一个现有的连接。', None, 10054, None)))
Traceback (most recent call last):
  File "D:\DEMO\Python_demo\Django_demo\Myflight\utils\data_get.py", line 376, in get_mesbyurl
    real_up = pytesseract.image_to_string(Image.open(filename))
  File "D:\DEMO\Python_demo\Django_demo\Myflight\venv\lib\site-packages\PIL\Image.py", line 2705, in open
    % (filename if filename else fp))
OSError: cannot identify image file './real_up.png'
Traceback (most recent call last):
  File "D:\DEMO\Python_demo\Django_demo\Myflight\venv\lib\site-packages\urllib3\connectionpool.py", line 600, in urlopen
    chunked=chunked)
  File "D:\DEMO\Python_demo\Django_demo\Myflight\venv\lib\site-packages\urllib3\connectionpool.py", line 384, in _make_request
    six.raise_from(e, None)
  File "<string>", line 2, in raise_from
  File "D:\DEMO\Python_demo\Django_demo\Myflight\venv\lib\site-packages\urllib3\connectionpool.py", line 380, in _make_request
    httplib_response = conn.getresponse()
  File "D:\application\anaconda\lib\http\client.py", line 1331, in getresponse
    response.begin()
  File "D:\application\anaconda\lib\http\client.py", line 297, in begin
    version, status, reason = self._read_status()
  File "D:\application\anaconda\lib\http\client.py", line 258, in _read_status
    line = str(self.fp.readline(_MAXLINE + 1), "iso-8859-1")
  File "D:\application\anaconda\lib\socket.py", line 586, in readinto
    return self._sock.recv_into(b)
ConnectionResetError: [WinError 10054] 远程主机强迫关闭了一个现有的连接。

During handling of the above exception, another exception occurred:

Traceback (most recent call last):
  File "D:\DEMO\Python_demo\Django_demo\Myflight\venv\lib\site-packages\requests\adapters.py", line 449, in send
    timeout=timeout
  File "D:\DEMO\Python_demo\Django_demo\Myflight\venv\lib\site-packages\urllib3\connectionpool.py", line 638, in urlopen
    _stacktrace=sys.exc_info()[2])
  File "D:\DEMO\Python_demo\Django_demo\Myflight\venv\lib\site-packages\urllib3\util\retry.py", line 398, in increment
    raise MaxRetryError(_pool, url, error or ResponseError(cause))
urllib3.exceptions.MaxRetryError: HTTPConnectionPool(host='119.97.237.74', port=80): Max retries exceeded with url: http://www.variflight.com/flight/detail/productImg&s=ck9COEdmS0Fwd1dTaXIvOFhtenNycytsdnBZPQ==&w=50&h=28&fontSize=13&fontColor=2f3032&background=ffffff?AE71649A58c77= (Caused by ProxyError('Cannot connect to proxy.', ConnectionResetError(10054, '远程主机强迫关闭了一个现有的连接。', None, 10054, None)))

During handling of the above exception, another exception occurred:

Traceback (most recent call last):
  File "D:\DEMO\Python_demo\Django_demo\Myflight\utils\data_get.py", line 372, in get_mesbyurl
    resp = r.get(url)
  File "D:\DEMO\Python_demo\Django_demo\Myflight\venv\lib\site-packages\requests\sessions.py", line 546, in get
    return self.request('GET', url, **kwargs)
  File "D:\DEMO\Python_demo\Django_demo\Myflight\venv\lib\site-packages\requests\sessions.py", line 533, in request
    resp = self.send(prep, **send_kwargs)
  File "D:\DEMO\Python_demo\Django_demo\Myflight\venv\lib\site-packages\requests\sessions.py", line 646, in send
    r = adapter.send(request, **kwargs)
  File "D:\DEMO\Python_demo\Django_demo\Myflight\venv\lib\site-packages\requests\adapters.py", line 510, in send
    raise ProxyError(e, request=request)
requests.exceptions.ProxyError: HTTPConnectionPool(host='119.97.237.74', port=80): Max retries exceeded with url: http://www.variflight.com/flight/detail/productImg&s=ck9COEdmS0Fwd1dTaXIvOFhtenNycytsdnBZPQ==&w=50&h=28&fontSize=13&fontColor=2f3032&background=ffffff?AE71649A58c77= (Caused by ProxyError('Cannot connect to proxy.', ConnectionResetError(10054, '远程主机强迫关闭了一个现有的连接。', None, 10054, None)))
Traceback (most recent call last):
  File "D:\DEMO\Python_demo\Django_demo\Myflight\venv\lib\site-packages\urllib3\connectionpool.py", line 600, in urlopen
    chunked=chunked)
  File "D:\DEMO\Python_demo\Django_demo\Myflight\venv\lib\site-packages\urllib3\connectionpool.py", line 384, in _make_request
    six.raise_from(e, None)
  File "<string>", line 2, in raise_from
  File "D:\DEMO\Python_demo\Django_demo\Myflight\venv\lib\site-packages\urllib3\connectionpool.py", line 380, in _make_request
    httplib_response = conn.getresponse()
  File "D:\application\anaconda\lib\http\client.py", line 1331, in getresponse
    response.begin()
  File "D:\application\anaconda\lib\http\client.py", line 297, in begin
    version, status, reason = self._read_status()
  File "D:\application\anaconda\lib\http\client.py", line 258, in _read_status
    line = str(self.fp.readline(_MAXLINE + 1), "iso-8859-1")
  File "D:\application\anaconda\lib\socket.py", line 586, in readinto
    return self._sock.recv_into(b)
ConnectionResetError: [WinError 10054] 远程主机强迫关闭了一个现有的连接。

During handling of the above exception, another exception occurred:

Traceback (most recent call last):
  File "D:\DEMO\Python_demo\Django_demo\Myflight\venv\lib\site-packages\requests\adapters.py", line 449, in send
    timeout=timeout
  File "D:\DEMO\Python_demo\Django_demo\Myflight\venv\lib\site-packages\urllib3\connectionpool.py", line 638, in urlopen
    _stacktrace=sys.exc_info()[2])
  File "D:\DEMO\Python_demo\Django_demo\Myflight\venv\lib\site-packages\urllib3\util\retry.py", line 398, in increment
    raise MaxRetryError(_pool, url, error or ResponseError(cause))
urllib3.exceptions.MaxRetryError: HTTPConnectionPool(host='119.97.237.74', port=80): Max retries exceeded with url: http://www.variflight.com/flight/detail/productImg&s=eEttaVRubWs2alRLWHk5eE11TGRiek9teHg0VVl4Z0Q=&w=63&h=28&fontSize=13&fontColor=2f3032&background=ffffff?AE71649A58c77= (Caused by ProxyError('Cannot connect to proxy.', ConnectionResetError(10054, '远程主机强迫关闭了一个现有的连接。', None, 10054, None)))

During handling of the above exception, another exception occurred:

Traceback (most recent call last):
  File "D:\DEMO\Python_demo\Django_demo\Myflight\utils\data_get.py", line 422, in get_mesbyurl
    q = r.get(ac)
  File "D:\DEMO\Python_demo\Django_demo\Myflight\venv\lib\site-packages\requests\sessions.py", line 546, in get
    return self.request('GET', url, **kwargs)
  File "D:\DEMO\Python_demo\Django_demo\Myflight\venv\lib\site-packages\requests\sessions.py", line 533, in request
    resp = self.send(prep, **send_kwargs)
  File "D:\DEMO\Python_demo\Django_demo\Myflight\venv\lib\site-packages\requests\sessions.py", line 646, in send
    r = adapter.send(request, **kwargs)
  File "D:\DEMO\Python_demo\Django_demo\Myflight\venv\lib\site-packages\requests\adapters.py", line 510, in send
    raise ProxyError(e, request=request)
requests.exceptions.ProxyError: HTTPConnectionPool(host='119.97.237.74', port=80): Max retries exceeded with url: http://www.variflight.com/flight/detail/productImg&s=eEttaVRubWs2alRLWHk5eE11TGRiek9teHg0VVl4Z0Q=&w=63&h=28&fontSize=13&fontColor=2f3032&background=ffffff?AE71649A58c77= (Caused by ProxyError('Cannot connect to proxy.', ConnectionResetError(10054, '远程主机强迫关闭了一个现有的连接。', None, 10054, None)))
Traceback (most recent call last):
  File "D:\DEMO\Python_demo\Django_demo\Myflight\venv\lib\site-packages\urllib3\connection.py", line 159, in _new_conn
    (self._dns_host, self.port), self.timeout, **extra_kw)
  File "D:\DEMO\Python_demo\Django_demo\Myflight\venv\lib\site-packages\urllib3\util\connection.py", line 80, in create_connection
    raise err
  File "D:\DEMO\Python_demo\Django_demo\Myflight\venv\lib\site-packages\urllib3\util\connection.py", line 70, in create_connection
    sock.connect(sa)
TimeoutError: [WinError 10060] 由于连接方在一段时间后没有正确答复或连接的主机没有反应，连接尝试失败。

During handling of the above exception, another exception occurred:

Traceback (most recent call last):
  File "D:\DEMO\Python_demo\Django_demo\Myflight\venv\lib\site-packages\urllib3\connectionpool.py", line 600, in urlopen
    chunked=chunked)
  File "D:\DEMO\Python_demo\Django_demo\Myflight\venv\lib\site-packages\urllib3\connectionpool.py", line 354, in _make_request
    conn.request(method, url, **httplib_request_kw)
  File "D:\application\anaconda\lib\http\client.py", line 1239, in request
    self._send_request(method, url, body, headers, encode_chunked)
  File "D:\application\anaconda\lib\http\client.py", line 1285, in _send_request
    self.endheaders(body, encode_chunked=encode_chunked)
  File "D:\application\anaconda\lib\http\client.py", line 1234, in endheaders
    self._send_output(message_body, encode_chunked=encode_chunked)
  File "D:\application\anaconda\lib\http\client.py", line 1026, in _send_output
    self.send(msg)
  File "D:\application\anaconda\lib\http\client.py", line 964, in send
    self.connect()
  File "D:\DEMO\Python_demo\Django_demo\Myflight\venv\lib\site-packages\urllib3\connection.py", line 181, in connect
    conn = self._new_conn()
  File "D:\DEMO\Python_demo\Django_demo\Myflight\venv\lib\site-packages\urllib3\connection.py", line 168, in _new_conn
    self, "Failed to establish a new connection: %s" % e)
urllib3.exceptions.NewConnectionError: <urllib3.connection.HTTPConnection object at 0x000001D67358ECF8>: Failed to establish a new connection: [WinError 10060] 由于连接方在一段时间后没有正确答复或连接的主机没有反应，连接尝试失败。

During handling of the above exception, another exception occurred:

Traceback (most recent call last):
  File "D:\DEMO\Python_demo\Django_demo\Myflight\venv\lib\site-packages\requests\adapters.py", line 449, in send
    timeout=timeout
  File "D:\DEMO\Python_demo\Django_demo\Myflight\venv\lib\site-packages\urllib3\connectionpool.py", line 638, in urlopen
    _stacktrace=sys.exc_info()[2])
  File "D:\DEMO\Python_demo\Django_demo\Myflight\venv\lib\site-packages\urllib3\util\retry.py", line 398, in increment
    raise MaxRetryError(_pool, url, error or ResponseError(cause))
urllib3.exceptions.MaxRetryError: HTTPConnectionPool(host='120.194.18.90', port=81): Max retries exceeded with url: http://www.variflight.com/flight/detail/productImg&s=M0tGZTgrNnBncFBqWC9MZ0VkVnlMdm1VdHlZPQ==&w=50&h=28&fontSize=13&fontColor=2f3032&background=ffffff?AE71649A58c77= (Caused by ProxyError('Cannot connect to proxy.', NewConnectionError('<urllib3.connection.HTTPConnection object at 0x000001D67358ECF8>: Failed to establish a new connection: [WinError 10060] 由于连接方在一段时间后没有正确答复或连接的主机没有反应，连接尝试失败。',)))

During handling of the above exception, another exception occurred:

Traceback (most recent call last):
  File "D:\DEMO\Python_demo\Django_demo\Myflight\utils\data_get.py", line 397, in get_mesbyurl
    resp = r.get(url)
  File "D:\DEMO\Python_demo\Django_demo\Myflight\venv\lib\site-packages\requests\sessions.py", line 546, in get
    return self.request('GET', url, **kwargs)
  File "D:\DEMO\Python_demo\Django_demo\Myflight\venv\lib\site-packages\requests\sessions.py", line 533, in request
    resp = self.send(prep, **send_kwargs)
  File "D:\DEMO\Python_demo\Django_demo\Myflight\venv\lib\site-packages\requests\sessions.py", line 646, in send
    r = adapter.send(request, **kwargs)
  File "D:\DEMO\Python_demo\Django_demo\Myflight\venv\lib\site-packages\requests\adapters.py", line 510, in send
    raise ProxyError(e, request=request)
requests.exceptions.ProxyError: HTTPConnectionPool(host='120.194.18.90', port=81): Max retries exceeded with url: http://www.variflight.com/flight/detail/productImg&s=M0tGZTgrNnBncFBqWC9MZ0VkVnlMdm1VdHlZPQ==&w=50&h=28&fontSize=13&fontColor=2f3032&background=ffffff?AE71649A58c77= (Caused by ProxyError('Cannot connect to proxy.', NewConnectionError('<urllib3.connection.HTTPConnection object at 0x000001D67358ECF8>: Failed to establish a new connection: [WinError 10060] 由于连接方在一段时间后没有正确答复或连接的主机没有反应，连接尝试失败。',)))
Traceback (most recent call last):
  File "D:\DEMO\Python_demo\Django_demo\Myflight\utils\data_get.py", line 376, in get_mesbyurl
    real_up = pytesseract.image_to_string(Image.open(filename))
  File "D:\DEMO\Python_demo\Django_demo\Myflight\venv\lib\site-packages\PIL\Image.py", line 2705, in open
    % (filename if filename else fp))
OSError: cannot identify image file './real_up.png'
Traceback (most recent call last):
  File "D:\DEMO\Python_demo\Django_demo\Myflight\utils\data_get.py", line 401, in get_mesbyurl
    real_down = pytesseract.image_to_string(Image.open(filename))
  File "D:\DEMO\Python_demo\Django_demo\Myflight\venv\lib\site-packages\PIL\Image.py", line 2705, in open
    % (filename if filename else fp))
OSError: cannot identify image file './real_down.png'
Traceback (most recent call last):
  File "D:\DEMO\Python_demo\Django_demo\Myflight\utils\data_get.py", line 425, in get_mesbyurl
    ac = pytesseract.image_to_string(Image.open(filename))
  File "D:\DEMO\Python_demo\Django_demo\Myflight\venv\lib\site-packages\PIL\Image.py", line 2705, in open
    % (filename if filename else fp))
OSError: cannot identify image file './ac.png'
Traceback (most recent call last):
  File "D:\DEMO\Python_demo\Django_demo\Myflight\utils\data_get.py", line 376, in get_mesbyurl
    real_up = pytesseract.image_to_string(Image.open(filename))
  File "D:\DEMO\Python_demo\Django_demo\Myflight\venv\lib\site-packages\PIL\Image.py", line 2705, in open
    % (filename if filename else fp))
OSError: cannot identify image file './real_up.png'
Traceback (most recent call last):
  File "D:\DEMO\Python_demo\Django_demo\Myflight\utils\data_get.py", line 401, in get_mesbyurl
    real_down = pytesseract.image_to_string(Image.open(filename))
  File "D:\DEMO\Python_demo\Django_demo\Myflight\venv\lib\site-packages\PIL\Image.py", line 2705, in open
    % (filename if filename else fp))
OSError: cannot identify image file './real_down.png'
Traceback (most recent call last):
  File "D:\DEMO\Python_demo\Django_demo\Myflight\utils\data_get.py", line 425, in get_mesbyurl
    ac = pytesseract.image_to_string(Image.open(filename))
  File "D:\DEMO\Python_demo\Django_demo\Myflight\venv\lib\site-packages\PIL\Image.py", line 2705, in open
    % (filename if filename else fp))
OSError: cannot identify image file './ac.png'
